Workbook

Sheet 商品總表
A1: 編號 | B1: 品牌 | C1: 系列 | D1: 品名 | E1: 商品編號 | F1: 外寬cm | G1: 外深cm | H1: 外高cm | I1: 內寬cm | J1: 內深cm | K1: 內高cm | L1: 材質 | M1: 顏色 | N1: 可堆疊 | O1: 附蓋 | P1: 售價NT$ | Q1: 查價日 | R1: 官網連結 | S1: 來源 | T1: 可信度 | U1: 備註 | V1: 套組／多件裝
A2: MUJI-001 | B2: MUJI | C2: PP整理盒 | D2: PP整理盒1 | E2: 4548076037309 | F2: 8.5 | G2: 8.5 | H2: 5 | L2: 聚丙烯 | O2: N | P2: 29 | Q2: 2026-10-26 | R2: https://shop.muji.tw/SalePage/Index/11704064 | S2: 官網 | T2: high | U2: 可將4種尺寸任意搭配；同系列：整理盒1(8.5×8.5)、2(8.5×25.5)、3(17×25.5)、4(11.5×34)，皆高5cm；整理盒1寬×2≈整理盒3寬(17)，整理盒1深×3=整理盒2深(25.5)；容量約240ml；品號MCL10A5A
A3: MUJI-002 | B3: MUJI | C3: PP整理盒 | D3: PP整理盒2 | E3: 4548076037316 | F3: 8.5 | G3: 25.5 | H3: 5 | L3: 聚丙烯 | O3: N | P3: 49 | Q3: 2026-10-26 | R3: https://shop.muji.tw/SalePage/Index/11704065 | S3: 官網 | T3: high | U3: 可將4種尺寸任意搭配；同系列：整理盒1(8.5×8.5)、2(8.5×25.5)、3(17×25.5)、4(11.5×34)，皆高5cm；整理盒1寬×2≈整理盒3寬(17)，整理盒1深×3=整理盒2深(25.5)；容量約800ml；品號MCL11A5A；線上另有舊款「PP整理盒2」(無染色，JAN 4550512057109，同尺寸，網路商店顯示已售完，SalePage 8959675)
A4: MUJI-003 | B4: MUJI | C4: PP整理盒 | D4: PP整理盒3 | E4: 4548076037330 | F4: 17 | G4: 25.5 | H4: 5 | L4: 聚丙烯 | O4: N | P4: 59 | Q4: 2026-10-26 | R4: https://shop.muji.tw/SalePage/Index/11704066 | S4: 官網 | T4: high | U4: 可將4種尺寸任意搭配；同系列：整理盒1(8.5×8.5)、2(8.5×25.5)、3(17×25.5)、4(11.5×34)，皆高5cm；整理盒1寬×2≈整理盒3寬(17)，整理盒1深×3=整理盒2深(25.5)；容量約1,700ml；品號MCL12A5A
A5: MUJI-004 | B5: MUJI | C5: PP整理盒 | D5: PP整理盒4 | E5: 4548076037347 | F5: 11.5 | G5: 34 | H5: 5 | L5: 聚丙烯 | O5: N | P5: 49 | Q5: 2026-10-26 | R5: https://shop.muji.tw/SalePage/Index/11704067 | S5: 官網 | T5: high | U5: 可將4種尺寸任意搭配；同系列：整理盒1(8.5×8.5)、2(8.5×25.5)、3(17×25.5)、4(11.5×34)，皆高5cm；整理盒1寬×2≈整理盒3寬(17)，整理盒1深×3=整理盒2深(25.5)；容量約1,500ml；品號MCL13A5A；線上另有舊款「PP整理盒4」(無染色，JAN 4550512057123，同尺寸，SalePage 8959676)
A6: MUJI-005 | B6: MUJI | C6: PP抽屜整理盒 | D6: PP抽屜整理盒(1)/100×100×40mm | E6: 4548718421541 | F6: 10 | G6: 10 | H6: 4 | L6: 聚丙烯 | O6: N | P6: 29 | Q6: 2026-10-26 | R6: https://shop.muji.tw/SalePage/Index/8917015 | S6: 官網 | T6: high | U6: 附隔間；共4種規格可組合用於不同尺寸抽屜；高4cm；產地日本；另售整理盒用隔板(型錄貨號18497997)
A7: MUJI-006 | B7: MUJI | C7: PP抽屜整理盒 | D7: PP抽屜整理盒(2)/100×200×40mm | E7: 4548718421558 | F7: 10 | G7: 20 | H7: 4 | L7: 聚丙烯 | O7: N | P7: 59 | Q7: 2026-10-26 | R7: https://shop.muji.tw/SalePage/Index/8916946 | S7: 官網 | T7: high | U7: 附隔間；共4種規格可組合用於不同尺寸抽屜；高4cm；產地日本；另售整理盒用隔板(型錄貨號18497997)；(1)×2=(2)
A8: MUJI-007 | B8: MUJI | C8: PP抽屜整理盒 | D8: PP抽屜整理盒(3)/67×200×40mm | E8: 4548718421565 | F8: 6.7 | G8: 20 | H8: 4 | L8: 聚丙烯 | O8: N | P8: 49 | Q8: 2026-10-26 | R8: https://shop.muji.tw/SalePage/Index/8916945 | S8: 官網 | T8: high | U8: 附隔間；共4種規格可組合用於不同尺寸抽屜；高4cm；產地日本；另售PP抽屜整理盒用隔板(3)(型錄貨號18498000)
A9: MUJI-008 | B9: MUJI | C9: PP抽屜整理盒 | D9: PP抽屜整理盒(4)/134×200×40mm | E9: 4548718421572 | F9: 13.4 | G9: 20 | H9: 4 | L9: 聚丙烯 | O9: N | P9: 59 | Q9: 2026-10-26 | R9: https://shop.muji.tw/SalePage/Index/8916928 | S9: 官網 | T9: high | U9: 附隔間；共4種規格可組合用於不同尺寸抽屜；高4cm；產地日本；另售PP抽屜整理盒用隔板(4)(型錄貨號18498017)；(3)×2=(4)寬
A10: MUJI-009 | B10: MUJI | C10: PP盒/抽屜式 | D10: PP盒/深型(正反疊) | E10: 4547315253586 | F10: 26 | G10: 37 | H10: 17.5 | I10: 22 | J10: 33.5 | K10: 14 | L10: 聚丙烯 | M10: 白灰/半透明 | N10: Y | O10: N | P10: 439 | Q10: 2026-10-26 | R10: https://shop.muji.tw/SalePage/Index/8920882 | S10: 官網 | T10: high | U10: 寬26×深37系列，可正反疊、互相堆疊；可加裝輪子(另售，加裝後高度約增3.8~4.2cm)；可放入SUS層架、自由組合層架；最高堆疊6層；耐重約4kg、抽屜上方約2kg；可收納約22片DVD；半透明款型錄貨號37192447(JAN 4549337192447)，官網特集頁 https://www.muji.com/tw/feature/polypropylene-storage/標示半透明款售價380元，與網路商店白灰款439元不同
A11: MUJI-010 | B11: MUJI | C11: PP盒/抽屜式 | D11: PP盒/深型/2格/附隔板(正反疊) | E11: 4550002108274 | F11: 26 | G11: 37 | H11: 17.5 | I11: 10.5 | J11: 33.5 | K11: 14 | L11: 聚丙烯 | M11: 白灰/半透明 | N11: Y | O11: N | P11: 669 | Q11: 2026-10-26 | R11: https://shop.muji.tw/SalePage/Index/8920941 | S11: 官網 | T11: high | U11: 寬26×深37系列，可正反疊、互相堆疊；可加裝輪子(另售，加裝後高度約增3.8~4.2cm)；可放入SUS層架、自由組合層架；2抽屜並排，內寸為單一抽屜；附4片分隔板(一抽屜可分4格)；最高堆疊6層；可收納約40片CD；半透明款型錄貨號76749028，特集頁標示半透明款640元
A12: MUJI-011 | B12: MUJI | C12: PP盒/抽屜式 | D12: PP盒/深型/窄/附隔板(正反疊) | E12: 4548076749035 | F12: 14 | G12: 37 | H12: 17.5 | I12: 10.5 | J12: 33.5 | K12: 14 | L12: 聚丙烯 | M12: 半透明 | N12: Y | O12: N | P12: 379 | Q12: 2026-10-26 | R12: https://shop.muji.tw/SalePage/Index/8920948 | S12: 官網 | T12: high | U12: 寬26×深37系列，可正反疊、互相堆疊；可加裝輪子(另售，加裝後高度約增3.8~4.2cm)；可放入SUS層架、自由組合層架；1/2寬單抽屜，適合縫隙；附2片分隔板；最高堆疊4層；約可收納20片CD；特集頁標示350元
A13: MUJI-012 | B13: MUJI | C13: PP盒/抽屜式 | D13: PP盒/淺型(正反疊) | E13: 4547315253579 | F13: 26 | G13: 37 | H13: 12 | I13: 22.5 | J13: 34 | K13: 8.5 | L13: 聚丙烯 | M13: 白灰/半透明 | N13: Y | O13: N | P13: 379 | Q13: 2026-10-26 | R13: https://shop.muji.tw/SalePage/Index/8920918 | S13: 官網 | T13: high | U13: 寬26×深37系列，可正反疊、互相堆疊；可加裝輪子(另售，加裝後高度約增3.8~4.2cm)；可放入SUS層架、自由組合層架；適合A4；最高堆疊10層；耐重約3kg；半透明款型錄貨號37192423，特集頁標示半透明款350元
A14: MUJI-013 | B14: MUJI | C14: PP盒/抽屜式 | D14: PP盒/淺型/2格/附隔板(正反疊) | E14: 4550002108304 | F14: 26 | G14: 37 | H14: 12 | I14: 10.5 | J14: 34 | K14: 8.5 | L14: 聚丙烯 | M14: 白灰/半透明 | N14: Y | O14: N | P14: 499 | Q14: 2026-10-26 | R14: https://shop.muji.tw/SalePage/Index/8920903 | S14: 官網 | T14: high | U14: 寬26×深37系列，可正反疊、互相堆疊；可加裝輪子(另售，加裝後高度約增3.8~4.2cm)；可放入SUS層架、自由組合層架；2抽屜並排，內寸為單一抽屜；附6片分隔板(一抽屜可分7格)；最高堆疊10層；半透明款型錄貨號76748984，特集頁標示460元
A15: MUJI-014 | B15: MUJI | C15: PP盒/抽屜式 | D15: PP盒/淺型/窄/附隔板(正反疊) | E15: 4548076749042 | F15: 14 | G15: 37 | H15: 12 | I15: 10.5 | J15: 34 | K15: 8.5 | L15: 聚丙烯 | M15: 半透明 | N15: Y | O15: N | P15: 349 | Q15: 2026-10-26 | R15: https://shop.muji.tw/SalePage/Index/8920967 | S15: 官網 | T15: high | U15: 寬26×深37系列，可正反疊、互相堆疊；可加裝輪子(另售，加裝後高度約增3.8~4.2cm)；可放入SUS層架、自由組合層架；1/2寬；附3片分隔板；最高堆疊6層；特集頁標示320元
A16: MUJI-015 | B16: MUJI | C16: PP盒/抽屜式 | D16: PP盒/淺型/3段(正反疊) | E16: 4549337192430 | F16: 26 | G16: 37 | H16: 32.5 | I16: 22.5 | J16: 34 | K16: 8.5 | L16: 聚丙烯 | M16: 半透明 | N16: Y | O16: N | P16: 799 | Q16: 2026-10-26 | R16: https://shop.muji.tw/SalePage/Index/8920920 | S16: 官網 | T16: high | U16: 寬26×深37系列，可正反疊、互相堆疊；可加裝輪子(另售，加裝後高度約增3.8~4.2cm)；可放入SUS層架、自由組合層架；3段抽屜一體，內寸為單一抽屜；最高堆疊3層；適合A4
A17: MUJI-016 | B17: MUJI | C17: PP盒/抽屜式 | D17: PP盒/淺型/6格/附隔板(正反疊) | E17: 4548076749004 | F17: 26 | G17: 37 | H17: 32.5 | I17: 10.5 | J17: 34 | K17: 8.5 | L17: 聚丙烯 | M17: 半透明 | N17: Y | O17: N | P17: 999 | Q17: 2026-10-26 | R17: https://shop.muji.tw/SalePage/Index/8920949 | S17: 官網 | T17: high | U17: 寬26×深37系列，可正反疊、互相堆疊；可加裝輪子(另售，加裝後高度約增3.8~4.2cm)；可放入SUS層架、自由組合層架；3段×2列共6抽屜，內寸為單一抽屜；附18片分隔板；最高堆疊3層
A18: MUJI-017 | B18: MUJI | C18: PP盒/抽屜式 | D18: PP盒/薄型(正反疊) | E18: 4550002108281 | F18: 26 | G18: 37 | H18: 9 | I18: 22.5 | J18: 34 | K18: 5.5 | L18: 聚丙烯 | M18: 白灰/半透明 | N18: Y | O18: N | P18: 349 | Q18: 2026-10-26 | R18: https://shop.muji.tw/SalePage/Index/8920959 | S18: 官網 | T18: high | U18: 寬26×深37系列，可正反疊、互相堆疊；可加裝輪子(另售，加裝後高度約增3.8~4.2cm)；可放入SUS層架、自由組合層架；最高堆疊13層；耐重約2kg；半透明款型錄貨號76749066，特集頁標示320元
A19: MUJI-018 | B19: MUJI | C19: PP盒/抽屜式 | D19: PP盒/薄型/2段(正反疊) | E19: 4548076749073 | F19: 26 | G19: 37 | H19: 16.5 | I19: 22.5 | J19: 34 | K19: 5.5 | L19: 聚丙烯 | M19: 半透明 | N19: Y | O19: N | P19: 499 | Q19: 2026-10-26 | R19: https://shop.muji.tw/SalePage/Index/8920954 | S19: 官網 | T19: high | U19: 寬26×深37系列，可正反疊、互相堆疊；可加裝輪子(另售，加裝後高度約增3.8~4.2cm)；可放入SUS層架、自由組合層架；2段抽屜一體，內寸為單一抽屜；最高堆疊7層；適合A4；特集頁標示560元，與網路商店/型錄499元不同
A20: MUJI-019 | B20: MUJI | C20: PP資料盒/橫式 | D20: PP資料盒/橫式/深型 | E20: 4550002108311 | F20: 37 | G20: 26 | H20: 17.5 | I20: 33.5 | J20: 22.5 | K20: 14 | L20: 聚丙烯 | M20: 白灰/半透明 | N20: Y | O20: N | P20: 439 | Q20: 2026-10-26 | R20: https://shop.muji.tw/SalePage/Index/8920896 | S20: 官網 | T20: high | U20: 寬37×深26橫式系列，可加裝輪子(另售)；可與PP收納架互相堆疊；適合A4；最高堆疊6層；抽屜1層約2kg、天板約5kg；半透明款型錄貨號15253791，特集頁標示410元
A21: MUJI-020 | B21: MUJI | C21: PP資料盒/橫式 | D21: PP資料盒/橫式/淺型 | E21: 4550002108328 | F21: 37 | G21: 26 | H21: 12 | I21: 33.5 | J21: 22.5 | K21: 8.5 | L21: 聚丙烯 | M21: 白灰/半透明 | N21: Y | O21: N | P21: 379 | Q21: 2026-10-26 | R21: https://shop.muji.tw/SalePage/Index/8920919 | S21: 官網 | T21: high | U21: 寬37×深26橫式系列，可加裝輪子(另售)；可與PP收納架互相堆疊；適合A4；最高堆疊10層；抽屜1層約1.5kg；半透明款型錄貨號15253784，特集頁標示380元
... A23: MUJI-022 | B23: MUJI | C23: PP資料盒/橫式 | D23: PP資料盒/橫式/薄型/2格 | E23: 4550002118990 | F23: 37 | G23: 26 | H23: 9 | I23: 16 | J23: 22.5 | K23: 5.5 | L23: 聚丙烯 | M23: 白灰/半透明 | N23: Y | O23: N | P23: 469 | Q23: 2026-10-26 | R23: https://shop.muji.tw/SalePage/Index/8920937 | S23: 官網 | T23: high | U23: 寬37×深26橫式系列，可加裝輪子(另售)；可與PP收納架互相堆疊；適合A4；2抽屜並排，內寸為單一抽屜；最高堆疊13層；半透明款型錄貨號15253777，特集頁標示560元，與網路商店/型錄469元不同
A24: MUJI-023 | B24: MUJI | C24: PP收納箱 | D24: PP收納箱/中型 | E24: 4550182219418 | F24: 37 | G24: 25 | H24: 16 | L24: 聚丙烯 | N24: Y | O24: N | P24: 199 | Q24: 2026-10-26 | R24: https://shop.muji.tw/SalePage/Index/8920914 | S24: 官網 | T24: high | U24: 尺寸可放入無印良品檔案盒；另售專用蓋(約37.5×25.5×2.5cm，129元)與內托盤；最高堆疊8層；耐重約5kg；內寸官方未標示
A25: MUJI-024 | B25: MUJI | C25: PP收納箱 | D25: PP收納箱/深型 | E25: 4550182219401 | F25: 37 | G25: 25 | H25: 31.5 | I25: 32 | J25: 20.5 | K25: 30 | L25: 聚丙烯 | N25: Y | O25: N | P25: 299 | Q25: 2026-10-26 | R25: https://shop.muji.tw/SalePage/Index/8920930 | S25: 官網 | T25: high | U25: 尺寸可放入無印良品檔案盒(檔案盒高24~31.8cm)；另售專用蓋(129元)與內托盤；最高堆疊4層；耐重約8kg
A26: MUJI-025 | B26: MUJI | C26: PP收納箱 | D26: PP收納箱內托盤 | E26: 4550182219449 | F26: 35 | G26: 23 | H26: 5.5 | L26: 聚丙烯 | O26: N | P26: 169 | Q26: 2026-10-26 | R26: https://shop.muji.tw/SalePage/Index/8920973 | S26: 官網 | T26: high | U26: PP收納箱(寬37×深25)系列專用內托盤，置於箱子上部；不可與舊款聚丙烯搬運箱一同使用；尺寸取自型錄P.25(貨號82219449)
A27: MUJI-026 | B27: MUJI | C27: PP附輪收納箱/追加用 | D27: PP追加用收納盒/高11cm | E27: 4547315880171 | F27: 18 | G27: 40 | H27: 11 | I27: 13 | J27: 36 | K27: 7 | L27: 聚丙烯 | N27: Y | O27: N | P27: 299 | Q27: 2026-10-26 | R27: https://shop.muji.tw/SalePage/Index/8920957 | S27: 官網 | T27: high | U27: 寬18×深40系列；可與附輪收納箱、專用輪(另售)組合；追加高度上限122cm(含輪)；最高堆疊10層；型錄稱「淺型」
A28: MUJI-027 | B28: MUJI | C28: PP附輪收納箱/追加用 | D28: PP追加用收納盒/高21cm | E28: 4945247721584 | F28: 18 | G28: 40 | H28: 21 | I28: 13 | J28: 35.5 | K28: 17 | L28: 聚丙烯 | N28: Y | O28: N | P28: 349 | Q28: 2026-10-26 | R28: https://shop.muji.tw/SalePage/Index/8920932 | S28: 官網 | T28: high | U28: 寬18×深40系列；可與附輪收納箱、專用輪(另售)組合；追加高度上限122cm(含輪)；最高堆疊5層；型錄稱「抽屜式」
A29: MUJI-028 | B29: MUJI | C29: PP附輪收納箱/追加用 | D29: PP追加用收納盒/高30.5cm | E29: 4547315880164 | F29: 18 | G29: 40 | H29: 30.5 | I29: 12.5 | J29: 35 | K29: 26.5 | L29: 聚丙烯 | N29: Y | O29: N | P29: 449 | Q29: 2026-10-26 | R29: https://shop.muji.tw/SalePage/Index/8920956 | S29: 官網 | T29: high | U29: 寬18×深40系列；可與附輪收納箱、專用輪(另售)組合；追加高度上限122cm(含輪)；最高堆疊4層；型錄稱「深型」
A30: MUJI-029 | B30: MUJI | C30: PP檔案盒 | D30: 聚丙烯檔案盒.標準型.A4用 | E30: 4550344902776 | F30: 10 | G30: 32 | H30: 24 | L30: 聚丙烯 | M30: 白灰 | O30: N | P30: 199 | Q30: 2026-10-26 | R30: https://shop.muji.tw/SalePage/Index/8919740 | S30: 官網 | T30: high | U30: 深32cm立式檔案盒系列；可直放或橫放；耐重約5kg；可放入PP收納箱深型；另售檔案盒用蓋/寬10cm用(79元，可裝輪子)；型錄另列未標色款貨號44902769
A31: MUJI-030 | B31: MUJI | C31: PP檔案盒 | D31: 聚丙烯檔案盒.標準型.寬.A4 | E31: 4550344902813 | F31: 15 | G31: 32 | H31: 24 | L31: 聚丙烯 | M31: 白灰 | O31: N | P31: 299 | Q31: 2026-10-26 | R31: https://shop.muji.tw/SalePage/Index/8919420 | S31: 官網 | T31: high | U31: 深32cm立式檔案盒系列；可直放或橫放；耐重約5kg；可放入兩本厚50mm的2孔檔案夾；網路商店規格寫「約長15x寬32x高24cm」，依型錄「約寬15×深32×高24cm」判讀；另售檔案盒用蓋/寬15cm用(99元)；型錄另列未標色款貨號44902806
A32: MUJI-031 | B32: MUJI | C32: PP檔案盒 | D32: 聚丙烯檔案盒.標準型.1/2 | F32: 10 | G32: 32 | H32: 12 | L32: 聚丙烯 | M32: 白灰 | N32: Y | O32: N | P32: 129 | Q32: 2026-10-26 | R32: https://shop.muji.tw/muji-journal/pdf/pdf/25AW-storage.pdf | S32: 型錄PDF | T32: medium | U32: 深32cm立式檔案盒系列；可直放或橫放；耐重約5kg；高度為標準型的1/2，最多可堆疊3層；網路商店查無此品項，僅見於型錄P.37(貨號44902752)，庫存請以門市為準
A33: MUJI-032 | B33: MUJI | C33: PP檔案盒 | D33: 聚丙烯檔案盒.標準型.寬.1/2 | E33: 4550344902790 | F33: 15 | G33: 32 | H33: 12 | L33: 聚丙烯 | M33: 白灰 | N33: Y | O33: N | P33: 199 | Q33: 2026-10-26 | R33: https://shop.muji.tw/SalePage/Index/8919406 | S33: 官網 | T33: high | U33: 深32cm立式檔案盒系列；可直放或橫放；耐重約5kg；標準型.寬的1/2高度，最多可堆疊3層
A34: MUJI-033 | B34: MUJI | C34: PP檔案盒 | D34: 聚丙烯檔案盒.標準型.1/2.25cm | E34: 4550344902882 | F34: 25 | G34: 32 | H34: 12 | L34: 聚丙烯 | N34: Y | O34: N | P34: 329 | Q34: 2026-10-26 | R34: https://shop.muji.tw/SalePage/Index/8919401 | S34: 官網 | T34: high | U34: 寬25cm、高度為系列1/2的立式檔案盒；搭配另售「聚丙烯立式檔案盒.標準型用蓋(可裝置輪子)」最多可堆疊3層
A35: MUJI-034 | B35: MUJI | C35: PP檔案盒 | D35: 聚丙烯立式斜口檔案盒.A4 | E35: 4550344902899 | F35: 10 | G35: 27.6 | H35: 31.8 | L35: 聚丙烯 | M35: 白灰 | O35: N | P35: 199 | Q35: 2026-10-26 | R35: https://shop.muji.tw/SalePage/Index/8919735 | S35: 官網 | T35: high | U35: 斜口設計，可收納A4加寬尺寸檔案夾；耐重約5kg；型錄另列未標色款貨號44902738
A36: MUJI-035 | B36: MUJI | C36: PP檔案盒 | D36: 聚丙烯立式斜口檔案盒.寬.A4 | E36: 4550344902912 | F36: 15 | G36: 27.6 | H36: 31.8 | L36: 聚丙烯 | M36: 白灰 | O36: N | P36: 299 | Q36: 2026-10-26 | R36: https://shop.muji.tw/SalePage/Index/8919737 | S36: 官網 | T36: high | U36: 可放入兩本厚50mm的2孔檔案夾；亦可收納A4加寬檔案夾；耐重約5kg；型錄另列未標色款貨號44902905
A37: MUJI-036 | B37: MUJI | C37: PP化妝盒(含再生聚丙烯) | D37: 含有再生聚丙烯化妝盒 | E37: 4550584465413 | F37: 15 | G37: 22 | H37: 16.9 | L37: 聚丙烯(含20%再生聚丙烯) | N37: Y | O37: N | P37: 119 | Q37: 2026-10-26 | R37: https://shop.muji.tw/SalePage/Index/11050118 | S37: 官網 | T37: high | U37: 同尺寸可堆疊；寬15cm系列，1/4、1/2、全高依序約4.5/8.6/16.9cm；品號OGB85A5S；另售含有再生聚丙烯化妝盒蓋/大(約15.7×23.2×2cm，59元)
A38: MUJI-037 | B38: MUJI | C38: PP化妝盒(含再生聚丙烯) | D38: 含有再生聚丙烯化妝盒1/2 | E38: 4550584465406 | F38: 15 | G38: 22 | H38: 8.6 | L38: 聚丙烯(含20%再生聚丙烯) | N38: Y | O38: N | P38: 109 | Q38: 2026-10-26 | R38: https://shop.muji.tw/SalePage/Index/11050116 | S38: 官網 | T38: high | U38: 同尺寸可堆疊；寬15cm系列，1/4、1/2、全高依序約4.5/8.6/16.9cm；品號OGB84A5S；另售化妝盒蓋/大(59元)
A39: MUJI-038 | B39: MUJI | C39: PP化妝盒(含再生聚丙烯) | D39: 含有再生聚丙烯化妝盒1/4 | E39: 4550584465390 | F39: 15 | G39: 22 | H39: 4.5 | L39: 聚丙烯(含20%再生聚丙烯) | N39: Y | O39: N | P39: 69 | Q39: 2026-10-26 | R39: https://shop.muji.tw/SalePage/Index/11050114 | S39: 官網 | T39: high | U39: 同尺寸可堆疊；寬15cm系列，1/4、1/2、全高依序約4.5/8.6/16.9cm；品號OGB83A5S；另售化妝盒蓋/大(59元)
A40: MUJI-039 | B40: MUJI | C40: PP化妝盒(含再生聚丙烯) | D40: 含有再生聚丙烯化妝盒1/2橫型 | E40: 4550584465383 | F40: 15 | G40: 11 | H40: 8.6 | L40: 聚丙烯(含20%再生聚丙烯) | N40: Y | O40: N | P40: 69 | Q40: 2026-10-26 | R40: https://shop.muji.tw/SalePage/Index/11050102 | S40: 官網 | T40: high | U40: 同尺寸可堆疊；寬15cm系列，1/4、1/2、全高依序約4.5/8.6/16.9cm；深度為化妝盒的1/2(11cm)，2個並排=化妝盒1/2；品號OGB82A5S；另售化妝盒蓋/小(約11.7×15.7×2cm，39元)
A41: MUJI-040 | B41: MUJI | C41: PP化妝盒(含再生聚丙烯) | D41: 含有再生聚丙烯化妝盒1/4橫型 | E41: 4550584465376 | F41: 15 | G41: 11 | H41: 4.5 | L41: 聚丙烯(含20%再生聚丙烯) | O41: N | P41: 59 | Q41: 2026-10-26 | R41: https://shop.muji.tw/SalePage/Index/11050100 | S41: 官網 | T41: high | U41: 同尺寸可堆疊；寬15cm系列，1/4、1/2、全高依序約4.5/8.6/16.9cm；品號OGB81A5S；另售化妝盒蓋/小(39元)
...

Sheet 收納配件
A1: 編號 | B1: 品牌 | C1: 類別 | D1: 品名 | E1: 商品編號 | F1: 最短cm | G1: 最長cm | H1: 寬cm | I1: 深cm | J1: 高cm | K1: 棒徑／線徑cm | L1: 耐重kg | M1: 安裝方式 | N1: 材質 | O1: 顏色 | P1: 售價NT$ | Q1: 查價日 | R1: 官網連結 | S1: 來源 | T1: 可信度 | U1: 官方建議用途 | V1: 備註
A2: MUJI-A001 | B2: MUJI | C2: 抽屜隔板 | D2: PP分隔板/大/4入 | E2: 4549738369622 | H2: 65.5 | I2: 0.2 | J2: 11 | M2: 免安裝 | N2: 聚苯乙烯樹脂(PS樹脂) | Q2: 2026-10-26 | R2: https://shop.muji.tw/SalePage/Index/8920955 | S2: 官網 | T2: high | U2: 可依所需間隔大小裁切、組合使用 | V2: SET:4549738369622|320|4|4;單片規格約寬65.5×深(厚)0.2×高11cm；品名雖為PP分隔板，官方材質標示為聚苯乙烯
A3: MUJI-A002 | B3: MUJI | C3: 抽屜隔板 | D3: PP分隔板/中/5入 | E3: 4549738369615 | H3: 36 | I3: 0.2 | J3: 7 | M3: 免安裝 | N3: 聚苯乙烯樹脂(PS樹脂) | Q3: 2026-10-26 | R3: https://shop.muji.tw/SalePage/Index/8920975 | S3: 官網 | T3: high | U3: 可依所需間隔大小裁切、組合使用 | V3: SET:4549738369615|180|5|5;單片規格約寬36×深(厚)0.2×高7cm；官方材質標示為聚苯乙烯
A4: MUJI-A003 | B4: MUJI | C4: 抽屜隔板 | D4: 可調整高度的不織布分隔袋/小/2入 | E4: 4550002110468 | H4: 11 | I4: 32.5 | J4: 21 | M4: 免安裝 | N4: 聚丙烯(不織布) | Q4: 2026-10-26 | R4: https://shop.muji.tw/SalePage/Index/8920989 | S4: 官網 | T4: high | U4: 適用各式收納用品的分隔袋，可反摺調整高度，也可用於天然素材收納用品 | V4: SET:4550002110468|260|2|2;單件W11×D32.5×H21cm；不可洗滌
A5: MUJI-A004 | B5: MUJI | C5: 抽屜隔板 | D5: 可調整高度的不織布分隔袋/中/2入 | E5: 4550002110475 | H5: 15 | I5: 32.5 | J5: 21 | M5: 免安裝 | N5: 聚丙烯(不織布) | Q5: 2026-10-26 | R5: https://shop.muji.tw/SalePage/Index/8920974 | S5: 官網 | T5: high | U5: 適用各式收納用品的分隔袋，可反摺調整高度，也可用於天然素材收納用品 | V5: SET:4550002110475|280|2|2;單件W15×D32.5×H21cm；網路商店於查詢日顯示已售完
A6: MUJI-A005 | B6: MUJI | C6: 抽屜隔板 | D6: 可調整高度的不織布分隔袋/大/2入 | E6: 4550002110482 | H6: 22.5 | I6: 32.5 | J6: 21 | M6: 免安裝 | N6: 聚丙烯(不織布) | Q6: 2026-10-26 | R6: https://shop.muji.tw/SalePage/Index/8920992 | S6: 官網 | T6: high | U6: 適用各式收納用品的分隔袋，可反摺調整高度；用於天然素材收納用品可防止衣物勾紗 | V6: SET:4550002110482|350|2|2;單件W22.5×D32.5×H21cm；網路商店於查詢日顯示已售完
A7: MUJI-A006 | B7: MUJI | C7: 抽屜隔板 | D7: PP抽屜整理盒用隔板(3) | E7: 4548718498000 | H7: 6.3 | I7: 0.25 | J7: 3 | M7: 嵌入式 | N7: 聚丙烯 | P7: 29 | Q7: 2026-10-26 | R7: https://shop.muji.tw/SalePage/Index/8917100 | S7: 官網 | T7: high | U7: PP抽屜整理盒專用隔板，採嵌入式設計，可依用途自行區隔大小 | V7: 官方規格「3×6.3×0.25cm」，依用途判讀為長6.3(填width)×厚0.25×高3；對應PP抽屜整理盒(3)(67×200×40mm)
A8: MUJI-A007 | B8: MUJI | C8: 抽屜隔板 | D8: PP抽屜整理盒用隔板(4) | E8: 4548718498017 | H8: 13 | I8: 0.25 | J8: 3 | M8: 嵌入式 | N8: 聚丙烯 | P8: 29 | Q8: 2026-10-26 | R8: https://shop.muji.tw/SalePage/Index/8917117 | S8: 官網 | T8: high | U8: PP抽屜整理盒專用隔板，採嵌入式設計，可依用途自行區隔大小 | V8: 官方規格「3×13×0.25cm」，依用途判讀為長13(填width)×厚0.25×高3；對應PP抽屜整理盒(4)(134×200×40mm)
A9: MUJI-A008 | B9: MUJI | C9: 抽屜隔板 | D9: 【零件】PP小物收納盒/3層用隔板 | E9: 4548718657063 | H9: 9.9 | I9: 9.1 | J9: 0.3 | M9: 嵌入式 | N9: 聚丙烯 | P9: 45 | Q9: 2026-10-26 | R9: https://shop.muji.tw/SalePage/Index/8919517 | S9: 官網 | T9: high | U9: PP小物收納盒/3層A4(貨號61164458)用隔板 | V9: 官方規格「9.9x9.1x0.3cm」，三值依原順序填入width/depth/height，方向未標示；對應的PP小物收納盒/3層本體在台灣網路商店查無
A10: MUJI-A009 | B10: MUJI | C10: 抽屜隔板 | D10: 【零件】聚丙烯小物收納盒/6層用分隔板 | E10: 4934761231259 | H10: 9.9 | I10: 3.8 | J10: 0.3 | M10: 嵌入式 | N10: 聚丙烯 | P10: 35 | Q10: 2026-10-26 | R10: https://shop.muji.tw/SalePage/Index/8919518 | S10: 官網 | T10: high | U10: 聚丙烯小物收納盒/6層(貨號61154909)用分隔板 | V10: 1入；官方規格「約9.9x3.8x0.3cm」，依原順序填入，方向未標示；對應本體在台灣網路商店查無
A11: MUJI-A010 | B11: MUJI | C11: 抽屜隔板 | D11: 聚苯乙烯分隔板.白灰.3分隔/大 | E11: 4550002856410 | H11: 27 | I11: 21 | J11: 16 | M11: 免安裝 | N11: 聚苯乙烯樹脂(PS樹脂) | O11: 白灰 | P11: 269 | Q11: 2026-10-26 | R11: https://shop.muji.tw/SalePage/Index/8916898 | S11: 官網 | T11: high | V11: 官方規格約270x210x160mm；3分隔，每分隔間距約83mm
A12: MUJI-A011 | B12: MUJI | C12: 抽屜隔板 | D12: 聚苯乙烯分隔板.白灰.3分隔/小 | E12: 4550002856427 | H12: 21 | I12: 13.5 | J12: 16 | M12: 免安裝 | N12: 聚苯乙烯樹脂(PS樹脂) | O12: 白灰 | P12: 199 | Q12: 2026-10-26 | R12: https://shop.muji.tw/SalePage/Index/8916929 | S12: 官網 | T12: high | V12: 官方規格約210x135x160mm；3分隔，每分隔間距約38mm；網路商店於查詢日顯示已售完
A13: MUJI-A012 | B13: MUJI | C13: 抽屜隔板 | D13: 鋼製分隔板.2分隔 | E13: 4550583767150 | H13: 8.6 | I13: 23 | J13: 11 | M13: 免安裝 | N13: 鋼(環氧樹脂粉體塗裝)、矽膠 | O13: 深灰 | P13: 690 | Q13: 2026-10-26 | R13: https://shop.muji.tw/SalePage/Index/10330664 | S13: 官網 | T13: high | U13: 收納用隔板，可放置書本、雜誌、筆記型電腦等；高度可與鋼製文具系列搭配 | V13: 官方規格約寬86×深230×高110mm；隔板間距約40mm；請勿堆疊或放重物
A14: MUJI-A013 | B14: MUJI | C14: 抽屜隔板 | D14: 鋼製書架隔板.小 | E14: 4550182603071 | H14: 10 | I14: 8 | J14: 10 | M14: 免安裝 | N14: 鋼 | P14: 79 | Q14: 2026-10-26 | R14: https://shop.muji.tw/SalePage/Index/8917007 | S14: 官網 | T14: high | U14: 書架隔板 | V14: 書擋型；官方規格10x8x10cm，依原順序填入
A15: MUJI-A014 | B15: MUJI | C15: 抽屜隔板 | D15: 鋼製書架隔板.中 | E15: 4550182603064 | H15: 12 | I15: 12 | J15: 17.5 | M15: 免安裝 | N15: 鋼 | P15: 99 | Q15: 2026-10-26 | R15: https://shop.muji.tw/SalePage/Index/8917030 | S15: 官網 | T15: high | U15: 書架隔板 | V15: 書擋型；官方規格12x12x17.5cm；網路商店於查詢日顯示已售完
A16: MUJI-A015 | B16: MUJI | C16: 抽屜隔板 | D16: 鋼製書架隔板.大 | E16: 4550182603057 | H16: 16 | I16: 15 | J16: 21 | M16: 免安裝 | N16: 鋼 | P16: 129 | Q16: 2026-10-26 | R16: https://shop.muji.tw/SalePage/Index/8916994 | S16: 官網 | T16: high | U16: 書架隔板 | V16: 書擋型；官方規格16x15x21cm；網路商店於查詢日顯示已售完
A17: MUJI-A016 | B17: MUJI | C17: 小型置物架 | D17: 壓克力隔板/26×17.5×10cm | E17: 4547315919833 | H17: 26 | I17: 17.5 | J17: 10 | M17: 免安裝 | N17: 丙烯系樹脂(壓克力) | O17: 透明 | P17: 219 | Q17: 2026-10-26 | R17: https://shop.muji.tw/SalePage/Index/8916974 | S17: 官網 | T17: high | U17: 用途多元的隔板，可用於分隔或擺放物品 | V17: ㄈ型層板加高架
A18: MUJI-A017 | B18: MUJI | C18: 小型置物架 | D18: 壓克力隔板/26×17.5×16cm | E18: 4547315919840 | H18: 26 | I18: 17.5 | J18: 16 | M18: 免安裝 | N18: 丙烯系樹脂(壓克力) | O18: 透明 | P18: 269 | Q18: 2026-10-26 | R18: https://shop.muji.tw/SalePage/Index/8916992 | S18: 官網 | T18: high | U18: 用途多元的隔板，可用於分隔或擺放物品 | V18: ㄈ型層板加高架
A19: MUJI-A018 | B19: MUJI | C19: 小型置物架 | D19: 不鏽鋼廚房立架 | E19: 4550344902394 | H19: 10 | I19: 20.5 | J19: 15 | M19: 免安裝 | N19: 18-8不鏽鋼 | P19: 300 | Q19: 2026-10-26 | R19: https://shop.muji.tw/SalePage/Index/8918348 | S19: 官網 | T19: high | U19: 收納餐具或砧板，瓶子或鍋蓋也可同時擺放 | V19: 請勿拖拉本體以免損傷洗碗槽
A20: MUJI-A019 | B20: MUJI | C20: 小型置物架 | D20: 相思木立架/不鏽鋼收納籃用 | E20: 4550584437083 | H20: 43 | I20: 31.5 | J20: 39.5 | L20: 5 | M20: 免安裝 | N20: 天然木(相思木) | P20: 890 | Q20: 2026-10-26 | R20: https://shop.muji.tw/SalePage/Index/10653130 | S20: 官網 | T20: high | U20: 可與不鏽鋼收納籃組合的立架(收納籃需另購) | V20: 耐重最大5kg，勿單側放置；品號PA12JJ5S
A21: MUJI-A020 | B21: MUJI | C21: 小型置物架 | D21: 不鏽鋼海綿架/吸盤式 | E21: 4550584794520 | H21: 6 | I21: 5 | J21: 7 | M21: 吸盤 | N21: 18-8不鏽鋼、吸盤:聚氯乙烯樹脂 | P21: 180 | Q21: 2026-10-26 | R21: https://shop.muji.tw/SalePage/Index/11580248 | S21: 官網 | T21: high | U21: 利用吸盤吸附於洗碗槽等平滑表面上 | V21: 品號MC13FA5S
A22: MUJI-A021 | B22: MUJI | C22: 掛勾 | D22: S掛鉤/防橫搖型/小/2入 | E22: 4549738755616 | H22: 5 | I22: 1 | J22: 9.5 | M22: 掛勾 | N22: 18-8不鏽鋼 | Q22: 2026-10-26 | R22: https://shop.muji.tw/SalePage/Index/8918240 | S22: 官網 | T22: high | U22: 用於懸掛小物 | V22: SET:4549738755616|140|2|2;單件約5×1×9.5cm；適用直徑2~3.5cm的橫桿；不易左右搖晃
A23: MUJI-A022 | B23: MUJI | C23: 掛勾 | D23: S掛鉤/防橫搖型/大/2入/7A | E23: 4549738755609 | H23: 7 | I23: 1.5 | J23: 14 | M23: 掛勾 | N23: 18-8不鏽鋼 | Q23: 2026-10-26 | R23: https://shop.muji.tw/SalePage/Index/8918252 | S23: 官網 | T23: high | U23: 用於懸掛小物 | V23: SET:4549738755609|260|2|2;單件約7×1.5×14cm；適用直徑3~5cm的橫桿；網路商店於查詢日顯示已售完
A24: MUJI-A023 | B24: MUJI | C24: 掛勾 | D24: 掛鉤/防橫搖型/小/3入 | E24: 4549738755630 | M24: 掛勾 | N24: 18-8不鏽鋼 | Q24: 2026-10-26 | R24: https://shop.muji.tw/SalePage/Index/8918231 | S24: 官網 | T24: high | V24: SET:4549738755630|130|3|3;最大可固定於直徑7.5mm的圓形桿；官方規格「約直徑1*2.5mm」意義不明，尺寸欄留空；網路商店於查詢日顯示已售完
A25: MUJI-A024 | B25: MUJI | C25: 掛勾 | D25: 掛鉤/防橫搖型/大/2入 | E25: 4549738755623 | M25: 掛勾 | N25: 18-8不鏽鋼 | Q25: 2026-10-26 | R25: https://shop.muji.tw/SalePage/Index/8918234 | S25: 官網 | T25: high | V25: SET:4549738755623|130|2|2;最大可固定於直徑14.5mm的圓形桿；官方規格「約直徑1.5×2.5cm」意義不明，尺寸欄留空；網路商店於查詢日顯示已售完
A26: MUJI-A025 | B26: MUJI | C26: 掛勾 | D26: 掛鉤/防橫搖型/長型 | E26: 4550584835797 | H26: 1.5 | I26: 6.5 | J26: 25 | L26: 2 | M26: 掛勾 | N26: 18-8不鏽鋼(電解拋光) | P26: 110 | Q26: 2026-10-26 | R26: https://shop.muji.tw/SalePage/Index/12052444 | S26: 官網 | T26: high | U26: 可上下掛用，有效利用空間 | V26: 適用直徑18mm以內的桿子；品號MAJ27A5S；網路商店於查詢日顯示已售完
A27: MUJI-A026 | B27: MUJI | C27: 掛勾 | D27: 鋁製S掛鉤/小 | E27: 4550182932386 | H27: 3 | J27: 5.5 | L27: 4 | M27: 掛勾 | N27: 鋁合金 | Q27: 2026-10-26 | R27: https://shop.muji.tw/SalePage/Index/8918274 | S27: 官網 | T27: high | V27: SET:4550182932386|50|3|3;單件約寬3×高5.5cm；可吊掛直徑約1.5cm圓柱形橫桿；耐重約4kg(官方未說明為單件或整組)
A28: MUJI-A027 | B28: MUJI | C28: 掛勾 | D28: 鋁製S掛鉤/中 | E28: 4550182932379 | H28: 4 | J28: 8.5 | L28: 4 | M28: 掛勾 | N28: 鋁合金 | Q28: 2026-10-26 | R28: https://shop.muji.tw/SalePage/Index/8918257 | S28: 官網 | T28: high | V28: SET:4550182932379|50|2|2;單件約寬4×高8.5cm；可吊掛直徑約2.5cm圓柱形橫桿；耐重約4kg(官方未說明為單件或整組)
A29: MUJI-A028 | B29: MUJI | C29: 掛勾 | D29: 鋁製S掛鉤/大 | E29: 4550182932362 | H29: 5.5 | J29: 11 | L29: 4 | M29: 掛勾 | N29: 鋁合金 | P29: 50 | Q29: 2026-10-26 | R29: https://shop.muji.tw/SalePage/Index/8918276 | S29: 官網 | T29: high | V29: 1入；約寬5.5×高11cm；可吊掛直徑約3cm圓柱形橫桿；耐重約4kg；網路商店於查詢日顯示已售完
A30: MUJI-A029 | B30: MUJI | C30: 掛勾 | D30: 不鏽鋼掛鉤/門用 | E30: 4549738755593 | H30: 3.5 | I30: 6 | J30: 6 | L30: 1 | M30: 掛門 | N30: 18-8不鏽鋼 | P30: 80 | Q30: 2026-10-26 | R30: https://shop.muji.tw/SalePage/Index/8918250 | S30: 官網 | T30: high | U30: 不需釘子或螺絲即可嵌入固定於門板上 | V30: 網路商店於查詢日顯示已售完
A31: MUJI-A030 | B31: MUJI | C31: 掛勾 | D31: 不鏽鋼掛鉤/門用/2連 | E31: 4550583923556 | H31: 6.5 | I31: 5.5 | J31: 6 | L31: 1 | M31: 掛門 | N31: 18-8不鏽鋼 | P31: 90 | Q31: 2026-10-26 | R31: https://shop.muji.tw/SalePage/Index/11863282 | S31: 官網 | T31: high | U31: 廚房、洗手台水槽櫃門用掛鉤，可掛毛巾或抹布 | V31: 適用厚度21mm以下的櫃門；耐重1kg(單邊500g)；品號MAJ13A4S；網路商店於查詢日顯示已售完
A32: MUJI-A031 | B32: MUJI | C32: 掛勾 | D32: 不鏽鋼雙頭S掛鉤/2連 | E32: 4550583923563 | H32: 6.5 | I32: 4.5 | J32: 6.5 | L32: 1 | M32: 掛勾 | N32: 18-8不鏽鋼 | P32: 90 | Q32: 2026-10-26 | R32: https://shop.muji.tw/SalePage/Index/10391413 | S32: 官網 | T32: high | U32: 可依吊掛物品或位置調整方向，用於吊掛小型物品或配件 | V32: 適合吊掛在直徑21mm或5mm的管線上；耐重約1kg(單邊約0.5kg)；網路商店於查詢日顯示已售完
A33: MUJI-A032 | B33: MUJI | C33: 掛勾 | D33: 不鏽鋼瓶用掛鉤/瀝水籃專用 | E33: 4550583923495 | H33: 3.5 | I33: 7 | J33: 13.5 | L33: 0.5 | M33: 掛勾 | N33: 18-8不鏽鋼 | P33: 90 | Q33: 2026-10-26 | R33: https://shop.muji.tw/SalePage/Index/10391411 | S33: 官網 | T33: high | U33: 掛在不鏽鋼瀝水籃上，用於晾乾清洗後的瓶罐和玻璃杯 | V33: 用於直徑5mm以下的管線
A34: MUJI-A033 | B34: MUJI | C34: 掛勾 | D34: 不鏽鋼絲夾/掛鉤式/4入/7A | E34: 4549738755586 | H34: 2 | I34: 5.5 | J34: 9.5 | M34: 掛勾 | N34: 18-8不鏽鋼 | Q34: 2026-10-26 | R34: https://shop.muji.tw/SalePage/Index/8918185 | S34: 官網 | T34: high | U34: 勾在桿上使用，懸吊食譜、抹布、橡膠手套等物品 | V34: SET:4549738755586|119|4|4;單件約寬2×深5.5×高9.5cm
A35: MUJI-A034 | B35: MUJI | C35: 掛勾 | D35: 旅行用S鉤 | E35: 4550002547431 | H35: 5 | J35: 9 | M35: 掛勾 | N35: POM樹脂 | O35: 淺灰 | P35: 140 | Q35: 2026-10-26 | R35: https://shop.muji.tw/SalePage/Index/8920758 | S35: 官網 | T35: high | U35: 旅行中吊掛物品；呈O型時可與鑰匙環、收納袋等連結 | V35: 官方規格「黑.約50x90mm」，與品名「淺灰」顏色不一致，color依品名
A36: MUJI-A035 | B36: MUJI | C36: 掛勾 | D36: 壁掛家具/掛鉤 | E36: 4550344162323/4550344162378 | H36: 4 | I36: 6 | J36: 8 | L36: 2 | M36: 壁掛(石膏板牆，無提供鑽牆螺絲) | N36: 天然木(橡木/胡桃木)、聚苯乙烯樹脂 | O36: 橡木/胡桃木 | P36: 300 | Q36: 2026-10-26 | R36: https://shop.muji.tw/SalePage/Index/8916062 | S36: 官網 | T36: high | U36: 可當帽架或外套掛勾(胡桃木款說明) | V36: 橡木款300元(JAN 4550344162323，SalePage 8916062)；胡桃木款350元(JAN 4550344162378，SalePage 12209053)；胡桃木款官方規格「長40×深60×高80mm」
A37: MUJI-A036 | B37: MUJI | C37: 掛勾 | D37: 壁掛家具/三連掛鉤/44cm | E37: 4550344504840/4550344504956 | H37: 44 | I37: 2.5 | J37: 10 | L37: 5 | M37: 壁掛(石膏板牆，無提供鑽牆螺絲) | N37: 天然木質裝飾單板貼面纖維板、天然木掛鉤 | O37: 橡木/胡桃木 | P37: 1190 | Q37: 2026-10-26 | R37: https://shop.muji.tw/SalePage/Index/12209056 | S37: 官網 | T37: high | U37: 適合用來掛帽子或外套 | V37: 耐重整體5kg、單個掛鉤2kg；官方規格「長440×深25×高100mm」；胡桃木款SalePage 12209059
A38: MUJI-A037 | B38: MUJI | C38: 吊掛收納 | D38: 不鏽鋼掛門式收納/毛巾用橫桿/大 | E38: 4550583923440 | H38: 37.5 | I38: 7.5 | J38: 5.5 | L38: 5 | M38: 掛門 | N38: 18-8不鏽鋼、墊片:發泡EVA | P38: 210 | Q38: 2026-10-26 | R38: https://shop.muji.tw/SalePage/Index/10391409 | S38: 官網 | T38: high | U38: 掛在廚房或浴室水槽門上的毛巾架 | V38: 可掛在厚度21mm以下的門上；耐熱80℃
A39: MUJI-A038 | B39: MUJI | C39: 吊掛收納 | D39: 不鏽鋼掛門式收納/毛巾用橫桿/小 | E39: 4550583923457 | H39: 20.5 | I39: 7.5 | J39: 5.5 | L39: 3 | M39: 掛門 | N39: 18-8不鏽鋼、墊片:發泡EVA | P39: 170 | Q39: 2026-10-26 | R39: https://shop.muji.tw/SalePage/Index/10391410 | S39: 官網 | T39: high | U39: 掛在廚房或浴室水槽門上的毛巾架 | V39: 可掛在厚度21mm以下的門上；耐熱80℃；網路商店於查詢日顯示已售完
A40: NITORI-A001 | B40: NITORI | C40: 伸縮棒 | D40: 極粗伸縮桿 NT 120-200cm | E40: 7450822 | F40: 120 | G40: 200 | K40: 2.2 | L40: 4 | M40: 伸縮撐壓 | N40: 鋼 | O40: 白色 | P40: 179 | Q40: 2026-10-26 | R40: https://www.nitori-net.tw/product/7450822 | S40: 官網 | T40: high | V40: 直徑19mm/22mm（細管/粗管）；mount依官網「耐重會因牆壁材質、伸縮長度、旋轉鬆緊度（撐緊力道）而有差異」判定為撐壓式；分類頁品名標示70-120cm，但線上僅見120-200cm規格；價格：查詢日售價179（原價199）
...

Sheet 收納技巧
A1: 編號 | B1: 空間 | C1: 主題 | D1: 技巧 | E1: 摘要 | F1: 步驟 | G1: 提到的盒子系列 | H1: 用到的配件 | I1: 相關品牌 | J1: 出處 | K1: 來源類型 | L1: 網址 | M1: 發布日 | N1: 查核日 | O1: 原文語言 | P1: 可信度
A2: TB-001 | B2: 廚房 | C2: 分區 | D2: 依水槽、備料台、爐台三條直線分區收納 | E2: 把廚房依「水槽一帶、備料台一帶、爐台一帶」縱向切開，各區只放該區用得到的東西，就能大致記住物品位置並縮短動線；同一區內再依使用頻率與重量決定放在高處或低處。 | I2: NITORI | J2: ニトリネット 収納アイデア｜キッチン・台所収納のアイデア | K2: 品牌官方 | L2: https://www.nitori-net.jp/ec/feature/storageidea/kitchen/ | M2: 2023-04-01 | N2: 2026-10-26 | O2: ja | P2: high
A3: TB-002 | B3: 層架 | C3: 高度利用/分區 | D3: 吊櫃上層放大盒、下層放小盒且不疊放 | E3: 吊櫃位置高、不易看清，避免直接把東西堆上去以免崩落，改用收納盒裝。不好拿的上層用必要數量的大盒，好拿的下層用小盒分裝；盒子彼此不要相疊，較輕的物品為主。 | I3: NITORI | J3: ニトリネット 収納アイデア｜キッチン・台所収納のアイデア | K3: 品牌官方 | L3: https://www.nitori-net.jp/ec/feature/storageidea/kitchen/ | M3: 2023-04-01 | N3: 2026-10-26 | O3: ja | P3: high
A4: TB-003 | B4: 廚房 | C4: 伸縮棒/高度利用 | D4: 高吊櫃用伸縮棒加一層 | E4: 吊櫃內部較高、想增加收納量時，可加裝伸縮棒或小層架做出第二層。伸縮棒有本身即可當棚板的款式，也有需另外在上面放棚板的款式，可依需求挑選。 | H4: 伸縮棒/伸縮層架/小型置物架 | I4: NITORI | J4: ニトリネット 収納アイデア｜キッチン・台所収納のアイデア | K4: 品牌官方 | L4: https://www.nitori-net.jp/ec/feature/storageidea/kitchen/ | M4: 2023-04-01 | N4: 2026-10-26 | O4: ja | P4: high
A5: TB-004 | B5: 廚房 | C5: 吊掛/高度利用 | D5: 吊櫃下方掛籃利用死角 | E5: 在吊櫃底板裝上可掛式籃子，就能使用吊櫃下方原本閒置的空間，適合放使用頻率高的物品；吊櫃下也可用掛勾直接吊掛常用工具，減少找與收的動作。 | H5: 吊掛收納/掛勾 | I5: NITORI | J5: ニトリネット 収納アイデア｜キッチン・台所収納のアイデア | K5: 品牌官方 | L5: https://www.nitori-net.jp/ec/feature/storageidea/kitchen/ | M5: 2023-04-01 | N5: 2026-10-26 | O5: ja | P5: high
A6: TB-005 | B6: 廚房 | C6: 壁面/浮空收納 | D6: 用磁吸收納把調味料移出檯面 | E6: 把原本直接放在檯面的調味料與廚具改用磁吸收納掛上牆，可保留備料空間並讓動線更順；牆面吸不住磁鐵時，可改用能吸磁的面板或可裝磁吸配件的伸縮立架。 | H6: 伸縮棒 | I6: NITORI | J6: ニトリネット 収納アイデア｜キッチン・台所収納のアイデア | K6: 品牌官方 | L6: https://www.nitori-net.jp/ec/feature/storageidea/kitchen/ | M6: 2023-04-01 | N6: 2026-10-26 | O6: ja | P6: high
A7: TB-006 | B7: 廚房 | C7: 縫隙/小型置物架 | D7: 爐台旁與後方縫隙放專用架 | E7: 爐台旁、爐台後方等不會拿來作業的位置是可利用點，選擇符合縫隙尺寸的架子放置調味料或工具；香料類集中到一個香料架，能避免作業檯面散亂。 | H7: 小型置物架 | I7: NITORI | J7: ニトリネット 収納アイデア｜キッチン・台所収納のアイデア | K7: 品牌官方 | L7: https://www.nitori-net.jp/ec/feature/storageidea/kitchen/ | M7: 2023-04-01 | N7: 2026-10-26 | O7: ja | P7: high
A8: TB-007 | B8: 水槽下 | C8: 避開管線/小型置物架 | D8: 對開門水槽下用避管架與滑軌盒 | E8: 對開門的水槽下要避開冷熱水與排水管，使用能繞過管線的收納架減少死角；再放入有深度與高度的滑出式收納，就能在櫃內做出類似抽屜的空間，收細小香料或較重的油品。 | H8: 小型置物架 | I8: NITORI | J8: ニトリネット 収納アイデア｜キッチン・台所収納のアイデア | K8: 品牌官方 | L8: https://www.nitori-net.jp/ec/feature/storageidea/kitchen/ | M8: 2023-04-01 | N8: 2026-10-26 | O8: ja | P8: high
A9: TB-008 | B9: 水槽下 | C9: 分區/防潮 | D9: 水槽下避免放食品與調味料 | E9: 水槽下因給水與排水，櫃內溫度與濕度容易升高，盡量不要放食品或調味料；適合放清潔劑、排水口濾網，沒有餐具櫃時也可放碗盤、瀝水籃與調理盆等水槽周邊用品。 | I9: NITORI | J9: ニトリネット 収納アイデア｜キッチン・台所収納のアイデア | K9: 品牌官方 | L9: https://www.nitori-net.jp/ec/feature/storageidea/kitchen/ | M9: 2023-04-01 | N9: 2026-10-26 | O9: ja | P9: high
A10: TB-009 | B10: 抽屜 | C10: 直立收納/抽屜隔板 | D10: 爐台下抽屜用隔板直立收鍋具 | E10: 從上方取物的抽屜，爐台下可用具隔板功能的立架，把平底鍋、鍋子與鍋蓋直立擺放，不會倒下且能依類別分開，拿取與歸位都更清楚。 | H10: 抽屜隔板 | I10: NITORI | J10: ニトリネット 収納アイデア｜キッチン・台所収納のアイデア | K10: 品牌官方 | L10: https://www.nitori-net.jp/ec/feature/storageidea/kitchen/ | M10: 2023-04-01 | N10: 2026-10-26 | O10: ja | P10: high
A11: TB-010 | B11: 抽屜 | C11: 直立收納 | D11: 深抽屜裡把盤子立起來放 | E11: 水槽下等較深的抽屜可把盤子立起收納，外觀整齊、取放順手，盤與盤之間不互相摩擦，也有助於減少破損；水槽下的抽屜也能把餐具、橡膠手套、垃圾袋放成從上方一眼好拿的狀態。 | H11: 抽屜隔板 | I11: NITORI | J11: ニトリネット 収納アイデア｜キッチン・台所収納のアイデア | K11: 品牌官方 | L11: https://www.nitori-net.jp/ec/feature/storageidea/kitchen/ | M11: 2023-04-01 | N11: 2026-10-26 | O11: ja | P11: high
A12: TB-011 | B12: 抽屜 | C12: 分區/伸縮 | D12: 淺抽屜用可伸縮整理盤填滿空間 | E12: 淺抽屜以「好找、好拿」為原則，配合抽屜尺寸使用整理盤；可伸縮的整理盤能拉開到抽屜寬度把空間用完，窄抽屜只放高頻物品，寬抽屜可一起收餐具與小工具。 | H12: 抽屜隔板 | I12: NITORI | J12: ニトリネット 収納アイデア｜キッチン・台所収納のアイデア | K12: 品牌官方 | L12: https://www.nitori-net.jp/ec/feature/storageidea/kitchen/ | M12: 2023-04-01 | N12: 2026-10-26 | O12: ja | P12: high
A13: TB-012 | B13: 廚房 | C13: 門板/吊掛 | D13: 櫃門內外側給小物找定位 | E13: 櫃門也是收納點：外側可掛毛巾或小垃圾桶，內側用黏貼或吸盤式收納放保鮮膜、隔熱手套、垃圾袋等平時不想露出的物品，用時一開門就拿得到。 | H13: 掛勾/吊掛收納 | I13: NITORI | J13: ニトリネット 収納アイデア｜キッチン・台所収納のアイデア | K13: 品牌官方 | L13: https://www.nitori-net.jp/ec/feature/storageidea/kitchen/ | M13: 2023-04-01 | N13: 2026-10-26 | O13: ja | P13: high
A14: TB-013 | B14: 廚房 | C14: 死角/小型置物架 | D14: 垃圾桶上方與冰箱旁放架子 | E14: 廚房裡冰箱與牆之間、垃圾桶上方等空間常被浪費；放入剛好塞得進的縫隙收納，或跨在垃圾桶上方的架子，可擺電鍋、微波爐等家電，減少死角。 | H14: 小型置物架 | I14: NITORI | J14: ニトリネット 収納アイデア｜キッチン・台所収納のアイデア | K14: 品牌官方 | L14: https://www.nitori-net.jp/ec/feature/storageidea/kitchen/ | M14: 2023-04-01 | N14: 2026-10-26 | O14: ja | P14: high
A15: TB-014 | B15: 衣櫃 | C15: 分區 | D15: 衣櫃分上、中、下段與門外側四區 | E15: 衣櫃先分區思考：上段放換季等低頻物；中段吊掛常穿衣物；下段放可摺衣物與較重物品，貼身衣物放收納箱；門的外側則作為包包、皮帶、外套等外出小物的暫放處。 | I15: NITORI | J15: ニトリネット 収納アイデア｜クローゼット収納のアイデア | K15: 品牌官方 | L15: https://www.nitori-net.jp/ec/feature/storageidea/closet/ | M15: 2023-04-01 | N15: 2026-10-26 | O15: ja | P15: high
A16: TB-015 | B16: 衣櫃 | C16: 高度利用/分區 | D16: 衣櫃上段用透明面或有把手的盒 | E16: 衣櫃上段不好拿，比起直接堆放，改用可疊放、防塵的收納盒；選正面透明或可快速打開的款式方便確認內容，輕量軟質或附把手的款式也較好上下搬動。 | I16: NITORI | J16: ニトリネット 収納アイデア｜クローゼット収納のアイデア | K16: 品牌官方 | L16: https://www.nitori-net.jp/ec/feature/storageidea/closet/ | M16: 2023-04-01 | N16: 2026-10-26 | O16: ja | P16: high
A17: TB-016 | B17: 衣櫃 | C17: 直立收納/分隔 | D17: 包包用書擋或檔案盒隔開立放 | E17: 包包這類形狀不一、無法自己站立的物品，可用書擋當隔板，或放進檔案盒、標準收納盒裡立著收，衣櫃上段也能整齊排列。 | H17: 抽屜隔板 | I17: NITORI | J17: ニトリネット 収納アイデア｜クローゼット収納のアイデア | K17: 品牌官方 | L17: https://www.nitori-net.jp/ec/feature/storageidea/closet/ | M17: 2023-04-01 | N17: 2026-10-26 | O17: ja | P17: high
A18: TB-017 | B18: 衣櫃 | C18: 吊掛/高度利用 | D18: 薄型與連結衣架增加吊掛量 | E18: 衣櫃寬度有限，可先換成薄型衣架增加可掛件數；褲裙或領帶、圍巾可用連結型衣架縱向串掛；毛衣、帽子等可放入掛在衣桿上的吊掛收納袋，甚至加掛一層吊衣桿把掛衣量加倍。 | H18: 吊掛收納 | I18: NITORI | J18: ニトリネット 収納アイデア｜クローゼット収納のアイデア | K18: 品牌官方 | L18: https://www.nitori-net.jp/ec/feature/storageidea/closet/ | M18: 2023-04-01 | N18: 2026-10-26 | O18: ja | P18: high
A19: TB-018 | B19: 衣櫃 | C19: 分區/統一 | D19: 衣櫃下段配合衣長疊盒並統一顏色 | E19: 衣櫃下段的基本做法是疊出層次增加收納量；先讓中段吊掛衣物的長度一致，下方就能依剩餘高度疊放收納盒。盒子全部統一同色，看起來更整齊。 | I19: NITORI | J19: ニトリネット 収納アイデア｜クローゼット収納のアイデア | K19: 品牌官方 | L19: https://www.nitori-net.jp/ec/feature/storageidea/closet/ | M19: 2023-04-01 | N19: 2026-10-26 | O19: ja | P19: high
A20: TB-019 | B20: 衣櫃 | C20: 伸縮棒/鐵網/吊掛 | D20: 衣櫃內加伸縮棒掛S鉤與鐵網 | E20: 衣櫃下段或側邊可裝伸縮棒並掛上S鉤，再搭配鐵網，就能吊掛清潔用具或包包等不易收進盒子的物品；門後與側壁這類空間適合放小物或細長物。 | H20: 伸縮棒/鐵網/掛勾 | I20: NITORI | J20: ニトリネット 収納アイデア｜クローゼット収納のアイデア | K20: 品牌官方 | L20: https://www.nitori-net.jp/ec/feature/storageidea/closet/ | M20: 2023-04-01 | N20: 2026-10-26 | O20: ja | P20: high
A21: TB-020 | B21: 衣櫃 | C21: 門板/吊掛 | D21: 衣櫃門外側掛門鉤當外套暫放處 | E21: 在衣櫃門外側裝門用掛勾，脫下的外套、帽子或每天用的包包可以直接掛上，比掛回中段衣桿方便很多；門上也可掛鏡子，讓換衣在衣櫃前完成。 | H21: 掛勾 | I21: NITORI | J21: ニトリネット 収納アイデア｜クローゼット収納のアイデア | K21: 品牌官方 | L21: https://www.nitori-net.jp/ec/feature/storageidea/closet/ | M21: 2023-04-01 | N21: 2026-10-26 | O21: ja | P21: high
A22: TB-021 | B22: 玄關 | C22: 伸縮棒/高度利用 | D22: 鞋櫃內用伸縮棒與鞋架增加層數 | E22: 檢討鞋子的擺法就能讓鞋櫃裝更多；可用鞋用疊放架或伸縮棒消除鞋櫃內的空隙。伸縮棒有直接當棚板的款式，也有另外放棚板的款式，依鞋櫃尺寸與鞋子數量選擇。 | H22: 伸縮棒/伸縮層架 | I22: NITORI | J22: ニトリネット 収納アイデア｜玄関収納のアイデア | K22: 品牌官方 | L22: https://www.nitori-net.jp/ec/feature/storageidea/entrance/ | M22: 2023-04-01 | N22: 2026-10-26 | O22: ja | P22: high
A23: TB-022 | B23: 玄關 | C23: 分類/盒子 | D23: 保養品與外出小物各裝一盒 | E23: 擦鞋海綿、鞋油等保養用品集中放進一個盒子，保養時整盒拿出即可；防蚊液、蚊香、防水噴霧、野餐墊等外出時用的零碎物品，也適合放在玄關並用盒子統一收。 | I23: NITORI | J23: ニトリネット 収納アイデア｜玄関収納のアイデア | K23: 品牌官方 | L23: https://www.nitori-net.jp/ec/feature/storageidea/entrance/ | M23: 2023-04-01 | N23: 2026-10-26 | O23: ja | P23: high
A24: TB-023 | B24: 玄關 | C24: 伸縮棒/吊掛 | D24: 鞋櫃內用伸縮棒吊掛長靴與雨傘 | E24: 長靴、雨傘等較長的物品，可在鞋櫃內用伸縮棒或毛巾架做出專門的吊掛區，把它們吊起來收納。鞋櫃大小每戶不同，要依自家鞋櫃尺寸與想收的東西規劃收法。 | H24: 伸縮棒/吊掛收納 | I24: NITORI | J24: ニトリネット 収納アイデア｜玄関収納のアイデア | K24: 品牌官方 | L24: https://www.nitori-net.jp/ec/feature/storageidea/entrance/ | M24: 2023-04-01 | N24: 2026-10-26 | O24: ja | P24: high
A25: TB-024 | B25: 玄關 | C25: 定位/門板 | D25: 鞋櫃上放托盤、門側掛拖鞋 | E25: 鞋櫃上方用小物盒或托盤給鑰匙、印章固定位置，避免檯面雜亂；拖鞋可掛在鞋櫃門外側或側面，地板空出來也比較好打掃。 | H25: 掛勾 | I25: NITORI | J25: ニトリネット 収納アイデア｜玄関収納のアイデア | K25: 品牌官方 | L25: https://www.nitori-net.jp/ec/feature/storageidea/entrance/ | M25: 2023-04-01 | N25: 2026-10-26 | O25: ja | P25: high
A26: TB-025 | B26: 玄關 | C26: 吊掛/磁吸 | D26: 玄關門用磁吸掛勾集中外出小物 | E26: 鑰匙、環保袋、口罩等帶出門的物品，可用磁吸收納掛在玄關門上集中管理；印章與酒精可放進瓶架或托盤。有小孩的家庭可依孩子拿得到與只有大人拿得到的高度分開收。 | H26: 掛勾/吊掛收納 | I26: NITORI | J26: ニトリネット 収納アイデア｜玄関収納のアイデア | K26: 品牌官方 | L26: https://www.nitori-net.jp/ec/feature/storageidea/entrance/ | M26: 2023-04-01 | N26: 2026-10-26 | O26: ja | P26: high
A27: TB-026 | B27: 玄關 | C27: 網片配件/壁面 | D27: 玄關牆面用洞洞板展示收納 | E27: 玄關牆面可用有孔板（洞洞板）、自行車架等做「展示型收納」收趣味用品；東西塞太滿會顯得雜亂，建議只放到約八成滿。 | H27: 網片配件 | I27: NITORI | J27: ニトリネット 収納アイデア｜玄関収納のアイデア | K27: 品牌官方 | L27: https://www.nitori-net.jp/ec/feature/storageidea/entrance/ | M27: 2023-04-01 | N27: 2026-10-26 | O27: ja | P27: high
A28: TB-027 | B28: 壁櫥 | C28: 分區 | D28: 壁櫥天袋前後分、頂層小分裝 | E28: 壁櫥最上層（天袋）不好取用，放低頻物品。因為很深，基本上前後分開：幾乎不拿的放後面、偶爾拿的放前面，並分成小份避免太重，盒子以有蓋款為佳。 | I28: NITORI | J28: ニトリネット 収納アイデア｜押入れ収納のアイデア | K28: 品牌官方 | L28: https://www.nitori-net.jp/ec/feature/storageidea/oshiire/ | N28: 2026-10-26 | O28: ja | P28: high
A29: TB-028 | B29: 壁櫥 | C29: 分區/滾輪 | D29: 壁櫥前後分區時，後方用滾輪收納 | E29: 壁櫥中下段若前後分開使用，常用物放前面、少用物放後面；前方放層架可搭配各種尺寸收納盒，後方則用附滾輪的衣物箱，讓後面的東西也能隨時拉出來。 | H29: 小型置物架 | I29: NITORI | J29: ニトリネット 収納アイデア｜押入れ収納のアイデア | K29: 品牌官方 | L29: https://www.nitori-net.jp/ec/feature/storageidea/oshiire/ | N29: 2026-10-26 | O29: ja | P29: high
A30: TB-029 | B30: 壁櫥 | C30: 伸縮棒/吊掛 | D30: 壁櫥下段用伸縮桿加支撐桿掛童裝 | E30: 把壁櫥下段當兒童空間時，用伸縮吊衣桿搭配支撐桿，掛再多衣服也不怕下滑；旁邊放壁櫥用收納箱收換季衣物，玩具與學用品則集中放入收納籃。 | H30: 伸縮棒/吊掛收納 | I30: NITORI | J30: ニトリネット 収納アイデア｜押入れ収納のアイデア | K30: 品牌官方 | L30: https://www.nitori-net.jp/ec/feature/storageidea/oshiire/ | N30: 2026-10-26 | O30: ja | P30: high
A31: TB-030 | B31: 浴室 | C31: 浮空收納/掛勾 | D31: 洗臉台上方用磁吸、吸盤、薄膜掛勾 | E31: 洗臉台上方放每天用的牙刷、吹風機等；需要瀝水的衛生用品改用磁鐵、吸盤或薄膜掛勾掛起來，比較衛生也更好打掃，可裝在塑膠面或鏡面等平整處。 | H31: 掛勾 | I31: NITORI | J31: ニトリネット 収納アイデア｜洗面所・脱衣所・トイレの収納アイデア | K31: 品牌官方 | L31: https://www.nitori-net.jp/ec/feature/storageidea/washroom/ | M31: 2023-04-01 | N31: 2026-10-26 | O31: ja | P31: high
A32: TB-031 | B32: 洗手台下 | C32: 避開管線/伸縮 | D32: 洗手台下用避管架與可伸縮盒 | E32: 洗手台下有排水管，可用能繞開管線的層架減少死角；再用符合深度的整理盒，選可伸縮的款式就能拉長到櫃深，連裡面的東西也好拿出。 | H32: 小型置物架 | I32: NITORI | J32: ニトリネット 収納アイデア｜洗面所・脱衣所・トイレの収納アイデア | K32: 品牌官方 | L32: https://www.nitori-net.jp/ec/feature/storageidea/washroom/ | M32: 2023-04-01 | N32: 2026-10-26 | O32: ja | P32: high
A33: TB-032 | B33: 洗手台下 | C33: 門板/掛勾 | D33: 洗手台櫃門內外側掛吹風機與日用品 | E33: 收納少的洗臉台可用門板：外側做每天用的吹風機掛點，內側用可撕除的薄膜掛勾或吸盤，把日用品藏在鏡櫃或門片裡側，減少生活感。 | H33: 掛勾 | I33: NITORI | J33: ニトリネット 収納アイデア｜洗面所・脱衣所・トイレの収納アイデア | K33: 品牌官方 | L33: https://www.nitori-net.jp/ec/feature/storageidea/washroom/ | M33: 2023-04-01 | N33: 2026-10-26 | O33: ja | P33: high
A34: TB-033 | B34: 浴室 | C34: 伸縮棒/高度利用 | D34: 洗衣機上方架伸縮棒放輕物 | E34: 洗衣機上方常是死角，可放洗衣機架或裝伸縮棒，放衣架、洗衣精等較輕的物品；設置前先確認伸縮棒長度足夠、耐重沒有問題。 | H34: 伸縮棒/伸縮層架 | I34: NITORI | J34: ニトリネット 収納アイデア｜洗面所・脱衣所・トイレの収納アイデア | K34: 品牌官方 | L34: https://www.nitori-net.jp/ec/feature/storageidea/washroom/ | M34: 2023-04-01 | N34: 2026-10-26 | O34: ja | P34: high
A35: TB-034 | B35: 浴室 | C35: 磁吸/縫隙 | D35: 洗衣機側面磁吸架與旁邊縫隙櫃 | E35: 洗衣機側面與正面可用磁吸收納掛洗衣球、衣架、毛巾，磁吸架兼有棚板與掛勾，放與掛一次完成；洗手台與洗衣機之間的縫隙則放細長推車或抽屜櫃。 | H35: 掛勾/小型置物架 | I35: NITORI | J35: ニトリネット 収納アイデア｜洗面所・脱衣所・トイレの収納アイデア | K35: 品牌官方 | L35: https://www.nitori-net.jp/ec/feature/storageidea/washroom/ | M35: 2023-04-01 | N35: 2026-10-26 | O35: ja | P35: high
A36: TB-035 | B36: 浴室 | C36: 伸縮棒/壁面 | D36: 馬桶後方牆面用伸縮棒做層架 | E36: 在馬桶後方牆面加裝伸縮棒或層板做收納，不會有壓迫感，空間小也能裝；沒有固定棚板時，用壁掛層架或伸縮棒就能多出放衛生紙等的位置。 | H36: 伸縮棒/伸縮層架 | I36: NITORI | J36: ニトリネット 収納アイデア｜洗面所・脱衣所・トイレの収納アイデア | K36: 品牌官方 | L36: https://www.nitori-net.jp/ec/feature/storageidea/washroom/ | M36: 2023-04-01 | N36: 2026-10-26 | O36: ja | P36: high
A37: TB-036 | B37: 桌面 | C37: 網片配件/掛勾 | D37: 書桌後方加裝洞洞板掛文具線材 | E37: 桌面上的東西容易散亂，可在桌子後側加裝洞洞板（パンチングボード），再配合可掛上的掛勾與托盤，把筆、眼鏡、線材等集中掛起，坐著就拿得到。 | H37: 網片配件/掛勾 | I37: NITORI | J37: ニトリネット 収納アイデア｜ワークスペースの収納アイデア | K37: 品牌官方 | L37: https://www.nitori-net.jp/ec/feature/storageidea/workspace/ | M37: 2023-04-01 | N37: 2026-10-26 | O37: ja | P37: high
A38: TB-037 | B38: 冰箱 | C38: 分區/高度利用 | D38: 冰箱上層放長期品、中下層放常備菜 | E38: 冷藏室上層較難看見與拿取，適合當長期保存的固定品（罐裝飲料、味噌等）的定位，並用有把手的托盤；中下層接近視線高度，放保存期限較短的常備菜與剩菜。 | I38: NITORI | J38: ニトリネット 特集｜見えるからムダがない！ニトリのおすすめ冷蔵庫収納 | K38: 品牌官方 | L38: https://www.nitori-net.jp/ec/feature/refrigerator/ | M38: 2023-07-26 | N38: 2026-10-26 | O38: ja | P38: high
A39: TB-038 | B39: 冰箱 | C39: 直立收納 | D39: 蔬果室下層用深盤把蔬菜立起來 | E39: 蔬果室上層放小東西與用剩的食材，下層用較深的托盤把葉菜、根莖類立起收；大小不一的食材可用可伸縮的托盤或收納盒整理。 | I39: NITORI | J39: ニトリネット 特集｜見えるからムダがない！ニトリのおすすめ冷蔵庫収納 | K39: 品牌官方 | L39: https://www.nitori-net.jp/ec/feature/refrigerator/ | M39: 2023-07-26 | N39: 2026-10-26 | O39: ja | P39: high
A40: TB-039 | B40: 冰箱 | C40: 直立收納/標籤 | D40: 冷凍庫立放、貼標並用隔板 | E40: 冷凍庫較深，冷凍食品不要疊放而是立起來；食材裝保存袋並貼標，方便定期檢查。夾鏈袋或冷凍食品不好站立時，可在托盤裡加隔板，讓家人也找得到。 | H40: 抽屜隔板 | I40: NITORI | J40: ニトリネット 特集｜見えるからムダがない！ニトリのおすすめ冷蔵庫収納 | K40: 品牌官方 | L40: https://www.nitori-net.jp/ec/feature/refrigerator/ | M40: 2023-07-26 | N40: 2026-10-26 | O40: ja | P40: high
...

Sheet 品牌摘要
A1: 品牌 | B1: 品項數 | C1: 有內寸 | D1: 單售有價格 | E1: 套組拆件／多件裝 | F1: 高可信度 | G1: 單售平均價NT$
A2: MUJI | B2: =COUNTIF(商品總表!$B$2:$B$485,A2) | C2: =COUNTIFS(商品總表!$B$2:$B$485,A2,商品總表!$I$2:$I$485,">0") | D2: =COUNTIFS(商品總表!$B$2:$B$485,A2,商品總表!$P$2:$P$485,">0") | E2: =COUNTIFS(商品總表!$B$2:$B$485,A2,商品總表!$V$2:$V$485,"整組*") | F2: =COUNTIFS(商品總表!$B$2:$B$485,A2,商品總表!$T$2:$T$485,"high") | G2: =IFERROR(ROUND(AVERAGEIF(商品總表!$B$2:$B$485,A2,商品總表!$P$2:$P$485),0),"-")
A3: NITORI | B3: =COUNTIF(商品總表!$B$2:$B$485,A3) | C3: =COUNTIFS(商品總表!$B$2:$B$485,A3,商品總表!$I$2:$I$485,">0") | D3: =COUNTIFS(商品總表!$B$2:$B$485,A3,商品總表!$P$2:$P$485,">0") | E3: =COUNTIFS(商品總表!$B$2:$B$485,A3,商品總表!$V$2:$V$485,"整組*") | F3: =COUNTIFS(商品總表!$B$2:$B$485,A3,商品總表!$T$2:$T$485,"high") | G3: =IFERROR(ROUND(AVERAGEIF(商品總表!$B$2:$B$485,A3,商品總表!$P$2:$P$485),0),"-")
A4: IKEA | B4: =COUNTIF(商品總表!$B$2:$B$485,A4) | C4: =COUNTIFS(商品總表!$B$2:$B$485,A4,商品總表!$I$2:$I$485,">0") | D4: =COUNTIFS(商品總表!$B$2:$B$485,A4,商品總表!$P$2:$P$485,">0") | E4: =COUNTIFS(商品總表!$B$2:$B$485,A4,商品總表!$V$2:$V$485,"整組*") | F4: =COUNTIFS(商品總表!$B$2:$B$485,A4,商品總表!$T$2:$T$485,"high") | G4: =IFERROR(ROUND(AVERAGEIF(商品總表!$B$2:$B$485,A4,商品總表!$P$2:$P$485),0),"-")
A5: DAISO | B5: =COUNTIF(商品總表!$B$2:$B$485,A5) | C5: =COUNTIFS(商品總表!$B$2:$B$485,A5,商品總表!$I$2:$I$485,">0") | D5: =COUNTIFS(商品總表!$B$2:$B$485,A5,商品總表!$P$2:$P$485,">0") | E5: =COUNTIFS(商品總表!$B$2:$B$485,A5,商品總表!$V$2:$V$485,"整組*") | F5: =COUNTIFS(商品總表!$B$2:$B$485,A5,商品總表!$T$2:$T$485,"high") | G5: =IFERROR(ROUND(AVERAGEIF(商品總表!$B$2:$B$485,A5,商品總表!$P$2:$P$485),0),"-")
A6: 合計 | B6: =SUM(B2:B5) | C6: =SUM(C2:C5) | D6: =SUM(D2:D5) | E6: =SUM(E2:E5) | F6: =SUM(F2:F5) | G6: =ROUND(AVERAGE(商品總表!$P$2:$P$485),0)
A8: 資料查詢日 2026-10-26。來源：MUJI shop.muji.tw＋官方收納型錄 25.12；NITORI nitori-net.tw；IKEA ikea.com.tw；大創見各列「來源」欄。
A9: 套組／多件裝的售價欄留空，整組價格寫在「套組／多件裝」欄；計算引擎會依整組件數換算購買組數。

Sheet 欄位說明
A1: 欄位 | B1: 說明
A2: 編號
A3: 品牌
A4: 系列
A5: 品名
A6: 商品編號
A7: 外寬cm | B7: 外寸寬（正面左右）
A8: 外深cm | B8: 外寸深（前後）
A9: 外高cm | B9: 外寸高
A10: 內寬cm | B10: 內寸寬，僅官方有標才填，不推算
A11: 內深cm | B11: 內寸深，同上
A12: 內高cm | B12: 內寸高，同上
A13: 材質
A14: 顏色 | B14: 多色以「/」分隔；單一顏色名含斜線時改用「+」
A15: 可堆疊 | B15: Y＝官方明確說可堆疊；空白＝官方未說明
A16: 附蓋 | B16: Y＝含蓋；另售蓋寫在備註
A17: 售價NT$ | B17: 查價日的官網單售價；套組與多件裝留空
A18: 查價日
A19: 官網連結
A20: 來源
A21: 可信度 | B21: high＝官網商品頁直接取得；medium＝型錄或來源間數值衝突（見備註）
A22: 備註 | B22: 套組列開頭為 SET:<套組編號>|<整組價>|<此尺寸件數>|<整組件數>; 供程式讀取
